Workbook

Sheet Cable
A1: Room Nr | B1: Connected to DF | C1: Length m | D1: Width m | E1: Size sqm | F1: Nr Dou_Outlets | G1: Dist_To_DF | H1: AVG_In Room | I1: Cable for room | J1: Room Type
A2: 1.1 | B2: MDF | C2: 6.5 | D2: 8.5 | E2: =C2*D2 -> 55.25 | F2: =ROUNDUP(E2/10,0) -> 6 | G2: 9.4 | H2: {=_xlfn.CEILING.MATH(_xlfn.SWITCH(J2, "A", 13.21, "B", 4.86, "C", 10.56, "D", 10.87, "E", 16.75, "F", 22, "G", 13.2, "H", 19.3, "I", 17.5, "J", 12.8, "K", 17.3, "L", 17, -1))} -> 14 | I2: =2*F2*(G2+H2+6) -> 352.8 | J2: A
A3: 1.2 | B3: MDF | C3: 8.5 | D3: 6.5 | E3: =C3*D3 -> 55.25 | F3: =ROUNDUP(E3/10,0) -> 6 | G3: 16.11 | H3: {=_xlfn.CEILING.MATH(_xlfn.SWITCH(J3, "A", 13.21, "B", 4.86, "C", 10.56, "D", 10.87, "E", 16.75, "F", 22, "G", 13.2, "H", 19.3, "I", 17.5, "J", 12.8, "K", 17.3, "L", 17, -1))} -> 5 | I3: =2*F3*(G3+H3+6) -> 325.32 | J3: B
A4: 1.3 | B4: MDF
A5: 1.4 | B5: MDF | C5: 5.5 | D5: 8.5 | E5: =C5*D5 -> 46.75 | F5: =ROUNDUP(E5/10,0) -> 5 | G5: 21.82 | H5: {=_xlfn.CEILING.MATH(_xlfn.SWITCH(J5, "A", 13.21, "B", 4.86, "C", 10.56, "D", 10.87, "E", 16.75, "F", 22, "G", 13.2, "H", 19.3, "I", 17.5, "J", 12.8, "K", 17.3, "L", 17, -1))} -> 11 | I5: =2*F5*(G5+H5+6) -> 388.2 | J5: C
A6: 1.5 | B6: MDF | C6: 5.5 | D6: 8.5 | E6: =C6*D6 -> 46.75 | F6: =ROUNDUP(E6/10,0) -> 5 | G6: 27.82 | H6: {=_xlfn.CEILING.MATH(_xlfn.SWITCH(J6, "A", 13.21, "B", 4.86, "C", 10.56, "D", 10.87, "E", 16.75, "F", 22, "G", 13.2, "H", 19.3, "I", 17.5, "J", 12.8, "K", 17.3, "L", 17, -1))} -> 11 | I6: =2*F6*(G6+H6+6) -> 448.2 | J6: C
A7: 1.6 | B7: MDF | C7: 5.5 | D7: 8.5 | E7: =C7*D7 -> 46.75 | F7: =ROUNDUP(E7/10,0) -> 5 | G7: 33.53 | H7: {=_xlfn.CEILING.MATH(_xlfn.SWITCH(J7, "A", 13.21, "B", 4.86, "C", 10.56, "D", 10.87, "E", 16.75, "F", 22, "G", 13.2, "H", 19.3, "I", 17.5, "J", 12.8, "K", 17.3, "L", 17, -1))} -> 11 | I7: =2*F7*(G7+H7+6) -> 505.3 | J7: C
A8: 1.7 | B8: MDF | C8: 5.5 | D8: 8.5 | E8: =C8*D8 -> 46.75 | F8: =ROUNDUP(E8/10,0) -> 5 | G8: 39.53 | H8: {=_xlfn.CEILING.MATH(_xlfn.SWITCH(J8, "A", 13.21, "B", 4.86, "C", 10.56, "D", 10.87, "E", 16.75, "F", 22, "G", 13.2, "H", 19.3, "I", 17.5, "J", 12.8, "K", 17.3, "L", 17, -1))} -> 11 | I8: =2*F8*(G8+H8+6) -> 565.3 | J8: C
A9: 1.8 | B9: MDF | C9: 5.5 | D9: 8.5 | E9: =C9*D9 -> 46.75 | F9: =ROUNDUP(E9/10,0) -> 5 | G9: 45.24 | H9: {=_xlfn.CEILING.MATH(_xlfn.SWITCH(J9, "A", 13.21, "B", 4.86, "C", 10.56, "D", 10.87, "E", 16.75, "F", 22, "G", 13.2, "H", 19.3, "I", 17.5, "J", 12.8, "K", 17.3, "L", 17, -1))} -> 11 | I9: =2*F9*(G9+H9+6) -> 622.4 | J9: C
A10: 1.9 | B10: BATHROOM
A11: 1.10
A12: 1.11 | B12: MDF | C12: 8.5 | D12: 11.5 | E12: =C12*D12 -> 97.75 | F12: =ROUNDUP(E12/10,0) -> 10 | G12: 0.5 | H12: {=_xlfn.CEILING.MATH(_xlfn.SWITCH(J12, "A", 13.21, "B", 4.86, "C", 10.56, "D", 10.87, "E", 16.75, "F", 22, "G", 13.2, "H", 19.3, "I", 17.5, "J", 12.8, "K", 17.3, "L", 17, -1))} -> 11 | I12: =2*F12*(G12+H12+6) -> 350 | J12: D
A13: 1.12 | B13: MDF | C13: 20 | D13: 16.5 | E13: =C13*D13 -> 330 | F13: =ROUNDUP(E13/10,0) -> 33 | G13: 5 | H13: {=_xlfn.CEILING.MATH(_xlfn.SWITCH(J13, "A", 13.21, "B", 4.86, "C", 10.56, "D", 10.87, "E", 16.75, "F", 22, "G", 13.2, "H", 19.3, "I", 17.5, "J", 12.8, "K", 17.3, "L", 17, -1))} -> 22 | I13: =2*F13*(G13+H13+6) -> 2178 | J13: F
A14: 1.13 | B14: MDF | C14: 6.5 | D14: 11.5 | E14: =C14*D14 -> 74.75 | F14: =ROUNDUP(E14/10,0) -> 8 | G14: 84.64 | H14: {=_xlfn.CEILING.MATH(_xlfn.SWITCH(J14, "A", 13.21, "B", 4.86, "C", 10.56, "D", 10.87, "E", 16.75, "F", 22, "G", 13.2, "H", 19.3, "I", 17.5, "J", 12.8, "K", 17.3, "L", 17, -1))} -> 17 | I14: =2*F14*(G14+H14+6) -> 1722.24 | J14: E
A15: 1.14 | B15: MDF | C15: 6.5 | D15: 11.5 | E15: =C15*D15 -> 74.75 | F15: =ROUNDUP(E15/10,0) -> 8 | G15: 91.78 | H15: {=_xlfn.CEILING.MATH(_xlfn.SWITCH(J15, "A", 13.21, "B", 4.86, "C", 10.56, "D", 10.87, "E", 16.75, "F", 22, "G", 13.2, "H", 19.3, "I", 17.5, "J", 12.8, "K", 17.3, "L", 17, -1))} -> 17 | I15: =2*F15*(G15+H15+6) -> 1836.48 | J15: E
A16: 1.15 | B16: MDF | C16: 6.5 | D16: 11.5 | E16: =C16*D16 -> 74.75 | F16: =ROUNDUP(E16/10,0) -> 8 | G16: 98.78 | H16: {=_xlfn.CEILING.MATH(_xlfn.SWITCH(J16, "A", 13.21, "B", 4.86, "C", 10.56, "D", 10.87, "E", 16.75, "F", 22, "G", 13.2, "H", 19.3, "I", 17.5, "J", 12.8, "K", 17.3, "L", 17, -1))} -> 17 | I16: =2*F16*(G16+H16+6) -> 1948.48 | J16: E
A17: 1.16 | B17: MDF | C17: 6.5 | D17: 11.5 | E17: =C17*D17 -> 74.75 | F17: =ROUNDUP(E17/10,0) -> 8 | G17: 105.92 | H17: {=_xlfn.CEILING.MATH(_xlfn.SWITCH(J17, "A", 13.21, "B", 4.86, "C", 10.56, "D", 10.87, "E", 16.75, "F", 22, "G", 13.2, "H", 19.3, "I", 17.5, "J", 12.8, "K", 17.3, "L", 17, -1))} -> 17 | I17: =2*F17*(G17+H17+6) -> 2062.72 | J17: E
A18: 1.17 | B18: MDF | C18: 6.5 | D18: 11.5 | E18: =C18*D18 -> 74.75 | F18: =ROUNDUP(E18/10,0) -> 8 | G18: 112.92 | H18: {=_xlfn.CEILING.MATH(_xlfn.SWITCH(J18, "A", 13.21, "B", 4.86, "C", 10.56, "D", 10.87, "E", 16.75, "F", 22, "G", 13.2, "H", 19.3, "I", 17.5, "J", 12.8, "K", 17.3, "L", 17, -1))} -> 17 | I18: =2*F18*(G18+H18+6) -> 2174.72 | J18: E
A19: 1.22 | B19: MDF | C19: 10 | D19: 20 | E19: =C19*D19 -> 200 | F19: =ROUNDUP(E19/10,0) -> 20 | G19: 17.5 | H19: {=_xlfn.CEILING.MATH(_xlfn.SWITCH(J19, "A", 13.21, "B", 4.86, "C", 10.56, "D", 10.87, "E", 16.75, "F", 22, "G", 13.2, "H", 19.3, "I", 17.5, "J", 12.8, "K", 17.3, "L", 17, -1))} -> 14 | I19: =2*F19*(G19+H19+6) -> 1500 | J19: G
A20: Subtotal MDF | F20: =SUM(F2:F19) -> 140 | I20: =SUM(I2:I19) -> 16980.16
A22: 1.18 | B22: IDF1 | C22: 6.5 | D22: 11.5 | E22: =C22*D22 -> 74.75 | F22: =ROUNDUP(E22/10,0) -> 8 | G22: 32 | H22: {=_xlfn.CEILING.MATH(_xlfn.SWITCH(J22, "A", 13.21, "B", 4.86, "C", 10.56, "D", 10.87, "E", 16.75, "F", 22, "G", 13.2, "H", 19.3, "I", 17.5, "J", 12.8, "K", 17.3, "L", 17, -1))} -> 17 | I22: =2*F22*(G22+H22+6) -> 880 | J22: E
A23: 1.19 | B23: IDF1 | C23: 6.5 | D23: 11.5 | E23: =C23*D23 -> 74.75 | F23: =ROUNDUP(E23/10,0) -> 8 | G23: 27 | H23: {=_xlfn.CEILING.MATH(_xlfn.SWITCH(J23, "A", 13.21, "B", 4.86, "C", 10.56, "D", 10.87, "E", 16.75, "F", 22, "G", 13.2, "H", 19.3, "I", 17.5, "J", 12.8, "K", 17.3, "L", 17, -1))} -> 17 | I23: =2*F23*(G23+H23+6) -> 800 | J23: E
A24: 1.20 | B24: BATHROOM
A25: 1.21
A26: 1.23 | B26: IDF1 | C26: 10 | D26: 20 | E26: =C26*D26 -> 200 | F26: =ROUNDUP(E26/10,0) -> 20 | G26: 0.5 | H26: {=_xlfn.CEILING.MATH(_xlfn.SWITCH(J26, "A", 13.21, "B", 4.86, "C", 10.56, "D", 10.87, "E", 16.75, "F", 22, "G", 13.2, "H", 19.3, "I", 17.5, "J", 12.8, "K", 17.3, "L", 17, -1))} -> 14 | I26: =2*F26*(G26+H26+6) -> 820 | J26: G
A27: 1.24 | B27: IDF1 | C27: 9 | D27: 10 | E27: =C27*D27 -> 90 | F27: =ROUNDUP(E27/10,0) -> 9 | G27: 45 | H27: {=_xlfn.CEILING.MATH(_xlfn.SWITCH(J27, "A", 13.21, "B", 4.86, "C", 10.56, "D", 10.87, "E", 16.75, "F", 22, "G", 13.2, "H", 19.3, "I", 17.5, "J", 12.8, "K", 17.3, "L", 17, -1))} -> 20 | I27: =2*F27*(G27+H27+6) -> 1278 | J27: H
A28: 1.25 | B28: IDF1 | C28: 9 | D28: 10 | E28: =C28*D28 -> 90 | F28: =ROUNDUP(E28/10,0) -> 9 | G28: 40 | H28: {=_xlfn.CEILING.MATH(_xlfn.SWITCH(J28, "A", 13.21, "B", 4.86, "C", 10.56, "D", 10.87, "E", 16.75, "F", 22, "G", 13.2, "H", 19.3, "I", 17.5, "J", 12.8, "K", 17.3, "L", 17, -1))} -> 20 | I28: =2*F28*(G28+H28+6) -> 1188 | J28: H
A29: 1.26 | B29: IDF1 | C29: 6.5 | D29: 9 | E29: =C29*D29 -> 58.5 | F29: =ROUNDUP(E29/10,0) -> 6 | G29: 12.54 | H29: {=_xlfn.CEILING.MATH(_xlfn.SWITCH(J29, "A", 13.21, "B", 4.86, "C", 10.56, "D", 10.87, "E", 16.75, "F", 22, "G", 13.2, "H", 19.3, "I", 17.5, "J", 12.8, "K", 17.3, "L", 17, -1))} -> 18 | I29: =2*F29*(G29+H29+6) -> 438.48 | J29: I
A30: 1.27 | B30: IDF1 | C30: 6.5 | D30: 9 | E30: =C30*D30 -> 58.5 | F30: =ROUNDUP(E30/10,0) -> 6 | G30: 21.88 | H30: {=_xlfn.CEILING.MATH(_xlfn.SWITCH(J30, "A", 13.21, "B", 4.86, "C", 10.56, "D", 10.87, "E", 16.75, "F", 22, "G", 13.2, "H", 19.3, "I", 17.5, "J", 12.8, "K", 17.3, "L", 17, -1))} -> 18 | I30: =2*F30*(G30+H30+6) -> 550.56 | J30: I
A31: 1.28 | B31: IDF1
A32: 1.29 | B32: IDF1 | C32: 4.5 | D32: 9.5 | E32: =C32*D32 -> 42.75 | F32: =ROUNDUP(E32/10,0) -> 5 | G32: 11.5 | H32: {=_xlfn.CEILING.MATH(_xlfn.SWITCH(J32, "A", 13.21, "B", 4.86, "C", 10.56, "D", 10.87, "E", 16.75, "F", 22, "G", 13.2, "H", 19.3, "I", 17.5, "J", 12.8, "K", 17.3, "L", 17, -1))} -> 13 | I32: =2*F32*(G32+H32+6) -> 305 | J32: J
A33: 1.30 | B33: IDF1 | C33: 4.5 | D33: 9.5 | E33: =C33*D33 -> 42.75 | F33: =ROUNDUP(E33/10,0) -> 5 | G33: 17 | H33: {=_xlfn.CEILING.MATH(_xlfn.SWITCH(J33, "A", 13.21, "B", 4.86, "C", 10.56, "D", 10.87, "E", 16.75, "F", 22, "G", 13.2, "H", 19.3, "I", 17.5, "J", 12.8, "K", 17.3, "L", 17, -1))} -> 13 | I33: =2*F33*(G33+H33+6) -> 360 | J33: J
A34: 1.31 | B34: IDF1 | C34: 4.5 | D34: 9.5 | E34: =C34*D34 -> 42.75 | F34: =ROUNDUP(E34/10,0) -> 5 | G34: 22.5 | H34: {=_xlfn.CEILING.MATH(_xlfn.SWITCH(J34, "A", 13.21, "B", 4.86, "C", 10.56, "D", 10.87, "E", 16.75, "F", 22, "G", 13.2, "H", 19.3, "I", 17.5, "J", 12.8, "K", 17.3, "L", 17, -1))} -> 13 | I34: =2*F34*(G34+H34+6) -> 415 | J34: J
A35: 1.32 | B35: IDF1 | C35: 4.5 | D35: 9.5 | E35: =C35*D35 -> 42.75 | F35: =ROUNDUP(E35/10,0) -> 5 | G35: 28 | H35: {=_xlfn.CEILING.MATH(_xlfn.SWITCH(J35, "A", 13.21, "B", 4.86, "C", 10.56, "D", 10.87, "E", 16.75, "F", 22, "G", 13.2, "H", 19.3, "I", 17.5, "J", 12.8, "K", 17.3, "L", 17, -1))} -> 13 | I35: =2*F35*(G35+H35+6) -> 470 | J35: J
A36: 1.33 | B36: IDF1 | C36: 4.5 | D36: 9.5 | E36: =C36*D36 -> 42.75 | F36: =ROUNDUP(E36/10,0) -> 5 | G36: 33.5 | H36: {=_xlfn.CEILING.MATH(_xlfn.SWITCH(J36, "A", 13.21, "B", 4.86, "C", 10.56, "D", 10.87, "E", 16.75, "F", 22, "G", 13.2, "H", 19.3, "I", 17.5, "J", 12.8, "K", 17.3, "L", 17, -1))} -> 13 | I36: =2*F36*(G36+H36+6) -> 525 | J36: J
A37: 1.34 | B37: BATHROOM
A38: 1.35
A39: 1.36 | B39: IDF1 | C39: 5.5 | D39: 12.5 | E39: =C39*D39 -> 68.75 | F39: =ROUNDUP(E39/10,0) -> 7 | G39: 10.5 | H39: {=_xlfn.CEILING.MATH(_xlfn.SWITCH(J39, "A", 13.21, "B", 4.86, "C", 10.56, "D", 10.87, "E", 16.75, "F", 22, "G", 13.2, "H", 19.3, "I", 17.5, "J", 12.8, "K", 17.3, "L", 17, -1))} -> 18 | I39: =2*F39*(G39+H39+6) -> 483 | J39: K
A40: 1.37 | B40: IDF1 | C40: 5.5 | D40: 12.5 | E40: =C40*D40 -> 68.75 | F40: =ROUNDUP(E40/10,0) -> 7 | G40: 17.5 | H40: {=_xlfn.CEILING.MATH(_xlfn.SWITCH(J40, "A", 13.21, "B", 4.86, "C", 10.56, "D", 10.87, "E", 16.75, "F", 22, "G", 13.2, "H", 19.3, "I", 17.5, "J", 12.8, "K", 17.3, "L", 17, -1))} -> 18 | I40: =2*F40*(G40+H40+6) -> 581 | J40: K
A41: 1.38 | B41: IDF1 | C41: 5.5 | D41: 12.5 | E41: =C41*D41 -> 68.75 | F41: =ROUNDUP(E41/10,0) -> 7 | G41: 23.5 | H41: {=_xlfn.CEILING.MATH(_xlfn.SWITCH(J41, "A", 13.21, "B", 4.86, "C", 10.56, "D", 10.87, "E", 16.75, "F", 22, "G", 13.2, "H", 19.3, "I", 17.5, "J", 12.8, "K", 17.3, "L", 17, -1))} -> 18 | I41: =2*F41*(G41+H41+6) -> 665 | J41: K
...

Sheet Fiber
A1: Fiber optic cable length
A2: Cable Source | C2: Target | E2: Length (m)
A3: A0 | C3: B0 | E3: 35
A4: B1 | C4: A1 | E4: 85
A5: C0 | C5: D0 | E5: 35
A6: D1 | C6: C1 | E6: 85
A7: A1 | C7: C1 | E7: 5
A8: D0 | C8: B0 | E8: 5
A9: A0 | C9: C0 | E9: 5
A10: D1 | C10: B1 | E10: 5
A12: Total fiber optic cable length | E12: =SUM(E3:F10) -> 260

Sheet Tech Stack
A1: Device | B1: Estimated Average Traffic [Mpbs]
A2: Workstation | B2: 25
A3: IP phone | B3: 0.1
A4: Access Point | B4: 300
A6: Concurrency factor | B6: 0.7
A9: Floor | B9: Room Type | D9: Number of rooms | E9: Total Estimated Traffic [Gbps] | F9: Estimated Traffic/Room [Gbps] | G9: Number of workstations | H9: Number of IP phones | I9: Number of access points | J9: Number of simple outlets
A10: GROUND FLOOR | B10: A | D10: 1 | E10: =F10*D10/1000 -> 0.38507 | F10: =SUM($B$2*G10,$B$3*H10,$B$4*I10)*$B$6 -> 385.07 | G10: 10 | H10: 1 | I10: 1 | J10: =SUM(G10:I10)*D10 -> 12
B11: B | D11: 1 | E11: =F11*D11/1000 -> 0.38507 | F11: =SUM($B$2*G11,$B$3*H11,$B$4*I11)*$B$6 -> 385.07 | G11: 10 | H11: 1 | I11: 1 | J11: =SUM(G11:I11)*D11 -> 12
B12: C | D12: 5 | E12: =F12*D12/1000 -> 1.75035 | F12: =SUM($B$2*G12,$B$3*H12,$B$4*I12)*$B$6 -> 350.07 | G12: 8 | H12: 1 | I12: 1 | J12: =SUM(G12:I12)*D12 -> 50
B13: D | D13: 1 | E13: =F13*D13/1000 -> 0.70014 | F13: =SUM($B$2*G13,$B$3*H13,$B$4*I13)*$B$6 -> 700.14 | G13: 16 | H13: 2 | I13: 2 | J13: =SUM(G13:I13)*D13 -> 20
B14: E | D14: 7 | E14: =F14*D14/1000 -> 3.18549 | F14: =SUM($B$2*G14,$B$3*H14,$B$4*I14)*$B$6 -> 455.07 | G14: 14 | H14: 1 | I14: 1 | J14: =SUM(G14:I14)*D14 -> 112
B15: F | D15: 1 | E15: =F15*D15/1000 -> 1.52257 | F15: =SUM($B$2*G15,$B$3*H15,$B$4*I15)*$B$6 -> 1522.57 | G15: 63 | H15: 1 | I15: 2 | J15: =SUM(G15:I15)*D15 -> 66
B16: G | D16: 2 | E16: =F16*D16/1000 -> 2.13514 | F16: =SUM($B$2*G16,$B$3*H16,$B$4*I16)*$B$6 -> 1067.57 | G16: 37 | H16: 1 | I16: 2 | J16: =SUM(G16:I16)*D16 -> 80
B17: H | D17: 2 | E17: =F17*D17/1000 -> 1.36514 | F17: =SUM($B$2*G17,$B$3*H17,$B$4*I17)*$B$6 -> 682.57 | G17: 15 | H17: 1 | I17: 2 | J17: =SUM(G17:I17)*D17 -> 36
B18: I | D18: 2 | E18: =F18*D18/1000 -> 0.77014 | F18: =SUM($B$2*G18,$B$3*H18,$B$4*I18)*$B$6 -> 385.07 | G18: 10 | H18: 1 | I18: 1 | J18: =SUM(G18:I18)*D18 -> 24
B19: J | D19: 5 | E19: =F19*D19/1000 -> 1.75035 | F19: =SUM($B$2*G19,$B$3*H19,$B$4*I19)*$B$6 -> 350.07 | G19: 8 | H19: 1 | I19: 1 | J19: =SUM(G19:I19)*D19 -> 50
B20: K | D20: 6 | E20: =F20*D20/1000 -> 2.52042 | F20: =SUM($B$2*G20,$B$3*H20,$B$4*I20)*$B$6 -> 420.07 | G20: 12 | H20: 1 | I20: 1 | J20: =SUM(G20:I20)*D20 -> 84
B21: L | D21: 0 | E21: =F21*D21/1000 -> 0 | F21: =SUM($B$2*G21,$B$3*H21,$B$4*I21)*$B$6 -> 420.07 | G21: 12 | H21: 1 | I21: 1 | J21: =SUM(G21:I21)*D21 -> 0
A22: FIRST FLOOR | B22: A | D22: 1 | E22: =F22*D22/1000 -> 0.38507 | F22: =SUM($B$2*G22,$B$3*H22,$B$4*I22)*$B$6 -> 385.07 | G22: 10 | H22: 1 | I22: 1 | J22: =SUM(G22:I22)*D22 -> 12
B23: B | D23: 1 | E23: =F23*D23/1000 -> 0.38507 | F23: =SUM($B$2*G23,$B$3*H23,$B$4*I23)*$B$6 -> 385.07 | G23: 10 | H23: 1 | I23: 1 | J23: =SUM(G23:I23)*D23 -> 12
B24: C | D24: 5 | E24: =F24*D24/1000 -> 1.75035 | F24: =SUM($B$2*G24,$B$3*H24,$B$4*I24)*$B$6 -> 350.07 | G24: 8 | H24: 1 | I24: 1 | J24: =SUM(G24:I24)*D24 -> 50
B25: D | D25: 1 | E25: =F25*D25/1000 -> 0.70014 | F25: =SUM($B$2*G25,$B$3*H25,$B$4*I25)*$B$6 -> 700.14 | G25: 16 | H25: 2 | I25: 2 | J25: =SUM(G25:I25)*D25 -> 20
B26: E | D26: 7 | E26: =F26*D26/1000 -> 3.18549 | F26: =SUM($B$2*G26,$B$3*H26,$B$4*I26)*$B$6 -> 455.07 | G26: 14 | H26: 1 | I26: 1 | J26: =SUM(G26:I26)*D26 -> 112
B27: F | D27: 1 | E27: =F27*D27/1000 -> 1.52257 | F27: =SUM($B$2*G27,$B$3*H27,$B$4*I27)*$B$6 -> 1522.57 | G27: 63 | H27: 1 | I27: 2 | J27: =SUM(G27:I27)*D27 -> 66
B28: G | D28: 2 | E28: =F28*D28/1000 -> 2.13514 | F28: =SUM($B$2*G28,$B$3*H28,$B$4*I28)*$B$6 -> 1067.57 | G28: 37 | H28: 1 | I28: 2 | J28: =SUM(G28:I28)*D28 -> 80
B29: H | D29: 0 | E29: =F29*D29/1000 -> 0 | F29: =SUM($B$2*G29,$B$3*H29,$B$4*I29)*$B$6 -> 682.57 | G29: 15 | H29: 1 | I29: 2 | J29: =SUM(G29:I29)*D29 -> 0
B30: I | D30: 2 | E30: =F30*D30/1000 -> 0.77014 | F30: =SUM($B$2*G30,$B$3*H30,$B$4*I30)*$B$6 -> 385.07 | G30: 10 | H30: 1 | I30: 1 | J30: =SUM(G30:I30)*D30 -> 24
B31: J | D31: 5 | E31: =F31*D31/1000 -> 1.75035 | F31: =SUM($B$2*G31,$B$3*H31,$B$4*I31)*$B$6 -> 350.07 | G31: 8 | H31: 1 | I31: 1 | J31: =SUM(G31:I31)*D31 -> 50
B32: K | D32: 6 | E32: =F32*D32/1000 -> 2.52042 | F32: =SUM($B$2*G32,$B$3*H32,$B$4*I32)*$B$6 -> 420.07 | G32: 12 | H32: 1 | I32: 1 | J32: =SUM(G32:I32)*D32 -> 84
B33: L | D33: 1 | E33: =F33*D33/1000 -> 0.42007 | F33: =SUM($B$2*G33,$B$3*H33,$B$4*I33)*$B$6 -> 420.07 | G33: 12 | H33: 1 | I33: 1 | J33: =SUM(G33:I33)*D33 -> 14
B34: Estimated peak traffic value in network [Gbps] | E34: =_xlfn.CEILING.MATH(SUM(E10:E33)) -> 32 | H34: Total number of simple outlets | J34: =SUM(J10:J33) -> 1070
H35: Total number of IP Phones | J35: =SUMPRODUCT(H10:H33,D10:D33) -> 67
H36: Total number of AP | J36: =SUMPRODUCT(I10:I33,D10:D33) -> 75
H37: Total number of WS | J37: =SUMPRODUCT(G10:G33,D10:D33) -> 928
A38: DF | B38: Number of WS | D38: Number of AP | E38: Number of IP Phones | F38: Number of Room Types Covered
F39: A | G39: B | H39: C | I39: D | J39: E | K39: F | L39: G | M39: H | N39: I | O39: J | P39: K | Q39: L
A40: MDF | B40: {=SUMPRODUCT(F40:Q40,TRANSPOSE($G$10:$G$21))} -> 246 | D40: {=SUMPRODUCT(F40:Q40,TRANSPOSE($I$10:$I$21))} -> 18 | E40: {=SUMPRODUCT(F40:Q40,TRANSPOSE($H$10:$H$21))} -> 16 | F40: 1 | G40: 1 | H40: 5 | I40: 1 | J40: 5 | K40: 1 | L40: 1 | M40: 0 | N40: 0 | O40: 0 | P40: 0 | Q40: 0
A41: IDF1 | B41: {=SUMPRODUCT(F41:Q41,TRANSPOSE($G$10:$G$21))} -> 227 | D41: {=SUMPRODUCT(F41:Q41,TRANSPOSE($I$10:$I$21))} -> 21 | E41: {=SUMPRODUCT(F41:Q41,TRANSPOSE($H$10:$H$21))} -> 18 | F41: 0 | G41: 0 | H41: 0 | I41: 0 | J41: 2 | K41: 0 | L41: 1 | M41: 2 | N41: 2 | O41: 5 | P41: 6 | Q41: 0
A42: IDF2 | B42: {=SUMPRODUCT(F42:Q42,TRANSPOSE($G$10:$G$21))} -> 246 | D42: {=SUMPRODUCT(F42:Q42,TRANSPOSE($I$10:$I$21))} -> 18 | E42: {=SUMPRODUCT(F42:Q42,TRANSPOSE($H$10:$H$21))} -> 16 | F42: 1 | G42: 1 | H42: 5 | I42: 1 | J42: 5 | K42: 1 | L42: 1 | M42: 0 | N42: 0 | O42: 0 | P42: 0 | Q42: 0
A43: IDF3 | B43: {=SUMPRODUCT(F43:Q43,TRANSPOSE($G$10:$G$21))} -> 209 | D43: {=SUMPRODUCT(F43:Q43,TRANSPOSE($I$10:$I$21))} -> 18 | E43: {=SUMPRODUCT(F43:Q43,TRANSPOSE($H$10:$H$21))} -> 17 | F43: 0 | G43: 0 | H43: 0 | I43: 0 | J43: 2 | K43: 0 | L43: 1 | M43: 0 | N43: 2 | O43: 5 | P43: 6 | Q43: 1
...

Sheet MDF
A1: Open Frame Server 44U Rack
A2: ORG Vert | B2: Spatiu ocupat in U | C2: Denumire/ tip echipament | D2: Model | E2: Scurta descriere/ nr porturi | F2: Putere electrica W | G2: Caldura disipata BTU/h | H2: ORG Vert
A3: Organizator de cabluri vertical | B3: 1 | C3: OF Patch Panel | D3: PP-72X100G-SMF | E3: 72 | H3: Organizator de cabluri vertical
B4: 13 | C4: Chassis | D4: Cisco Catalyst 9410R
C5: Supervisor | D5: ='Tech Stack'!B52 -> C9400-SUP-1XL | E5: 2 | F5: 350 | G5: =ABS(F5)*3.41 -> 1193.5
C6: Supervisor | D6: ='Tech Stack'!B52 -> C9400-SUP-1XL | E6: 2 | F6: 350 | G6: =ABS(F6)*3.41 -> 1193.5
C7: OF Line Card | D7: ='Tech Stack'!B56 -> C9400-LC-12QC (12x40GE) | E7: 12 | F7: 280 | G7: =ABS(F7)*3.41 -> 954.8
C8: Line Card (WS) | D8: ='Tech Stack'!B53 -> C9400-LC-48P | E8: 48 | F8: =(65) -> 65 | G8: =(ABS(F8)*3.41) -> 221.65
C9: Line Card (WS) | D9: ='Tech Stack'!B53 -> C9400-LC-48P | E9: 48 | F9: =(65) -> 65 | G9: =(ABS(F9)*3.41) -> 221.65
C10: Line Card (WS) | D10: ='Tech Stack'!B53 -> C9400-LC-48P | E10: 48 | F10: =(65) -> 65 | G10: =(ABS(F10)*3.41) -> 221.65
C11: Line Card (WS) | D11: ='Tech Stack'!B53 -> C9400-LC-48P | E11: 48 | F11: =(65) -> 65 | G11: =(ABS(F11)*3.41) -> 221.65
C12: Line Card (WS) | D12: ='Tech Stack'!B53 -> C9400-LC-48P | E12: 48 | F12: =(65) -> 65 | G12: =(ABS(F12)*3.41) -> 221.65
C13: Line Card (IP Phone) | D13: ='Tech Stack'!B53 -> C9400-LC-48P | E13: 48 | F13: =(20*30*1.3+65) -> 845 | G13: 250
C14: Line Card (AP) | D14: ='Tech Stack'!B57 -> C9400-LC-48UX | E14: 48 | F14: =(20*60*1.3+70) -> 1630 | G14: 250 | J14: Power required in chassis | K14: =SUM(F5:F14,F23) -> 4380
C15: Power Supply | D15: PWR-C4-3200WAC | F15: 3200 | G15: 950 | J15: Power provided by chassis | K15: =SUM(F15:F22) -> 9600
C16: Power Supply | D16: PWR-C4-3200WAC | F16: 3200 | G16: 950
C17: Power Supply | D17: PWR-C4-3200WAC | F17: 3200 | G17: 950
C18: Power Supply | G18: =ABS(F18)*3.41 -> 0
C19: Power Supply | G19: =ABS(F19)*3.41 -> 0
C20: Power Supply | G20: =ABS(F20)*3.41 -> 0
C21: Power Supply | G21: =ABS(F21)*3.41 -> 0
C22: Power Supply | G22: =ABS(F22)*3.41 -> 0
C23: Catalyst 9410R Fan Tray | D23: C9410-FAN | F23: 600 | G23: =ABS(F23)*3.41 -> 2046
B24: 2 | C24: UTP Patch Panel | D24: CPPKL6ATG48WBL | E24: 48
B25: 2 | C25: UTP Patch Panel | D25: CPPKL6ATG48WBL | E25: 48
B26: 2 | C26: UTP Patch Panel | D26: CPPKL6ATG48WBL | E26: 48
B27: 2 | C27: UTP Patch Panel | D27: CPPKL6ATG48WBL | E27: 48
B28: 2 | C28: UTP Patch Panel | D28: CPPKL6ATG48WBL | E28: 48
B29: 2 | C29: UTP Patch Panel | D29: CPPKL6ATG48WBL | E29: 48
B30: 2 | C30: UTP Patch Panel | D30: CPPKL6ATG48WBL | E30: 48
B31: 2 | C31: EMPTY SPACE FOR VENTILATION
B33: 1 | C33: Firewall | D33: ='Tech Stack'!B59 -> Cisco Secure Firewall 4245 | F33: 1380 | G33: 3000
C34: Firewall 4245 Fan Module | D34: FPR4200-FAN | F34: 45 | G34: =ABS(F34)*3.41 -> 153.45
C35: Firewall 4245 Fan Module | D35: FPR4200-FAN | F35: 45 | G35: =ABS(F35)*3.41 -> 153.45
C36: Firewall 4245 Fan Module | D36: FPR4200-FAN | F36: 45 | G36: =ABS(F36)*3.41 -> 153.45
B37: 2 | C37: EMPTY SPACE FOR VENTILATION
B39: 6 | C39: UPS | D39: SRT10KXLT | F39: 10000 | G39: 2450
B40: 6 | C40: UPS | D40: SRT10KXLT | F40: 10000 | G40: 2450
A41: Total | B41: =SUM(B4:B40) -> 44 | G41: =SUM(G4:G40) -> 18206.4
E42: Required UPS power [W] | F42: =SUM(F33:F36,F15:F22) -> 11115
...

Sheet IDF1
A1: Open Frame Server 44U Rack
A2: ORG Vert | B2: Spatiu ocupat in U | C2: Denumire/ tip echipament | D2: Model | E2: Scurta descriere/ nr porturi | F2: Putere electrica W | G2: Caldura disipata BTU/h | H2: ORG Vert
A3: Organizator de cabluri vertical | B3: 1 | C3: OF Patch Panel | D3: PP-72X100G-SMF | E3: 72 | H3: Organizator de cabluri vertical
B4: 13 | C4: Chassis | D4: Cisco Catalyst 9410R
C5: Supervisor | D5: ='Tech Stack'!B52 -> C9400-SUP-1XL | E5: 2 | F5: 350 | G5: =ABS(F5)*3.41 -> 1193.5
C6: Supervisor | D6: ='Tech Stack'!B52 -> C9400-SUP-1XL | E6: 2 | F6: 350 | G6: =ABS(F6)*3.41 -> 1193.5
C7: OF Line Card | D7: ='Tech Stack'!B56 -> C9400-LC-12QC (12x40GE) | E7: 12 | F7: 280 | G7: =ABS(F7)*3.41 -> 954.8
C8: Line Card (WS) | D8: ='Tech Stack'!B53 -> C9400-LC-48P | E8: 48 | F8: =(65) -> 65 | G8: =(ABS(F8)*3.41) -> 221.65
C9: Line Card (WS) | D9: ='Tech Stack'!B53 -> C9400-LC-48P | E9: 48 | F9: =(65) -> 65 | G9: =(ABS(F9)*3.41) -> 221.65
C10: Line Card (WS) | D10: ='Tech Stack'!B53 -> C9400-LC-48P | E10: 48 | F10: =(65) -> 65 | G10: =(ABS(F10)*3.41) -> 221.65
C11: Line Card (WS) | D11: ='Tech Stack'!B53 -> C9400-LC-48P | E11: 48 | F11: =(65) -> 65 | G11: =(ABS(F11)*3.41) -> 221.65
C12: Line Card (WS) | D12: ='Tech Stack'!B53 -> C9400-LC-48P | E12: 48 | F12: =(65) -> 65 | G12: =(ABS(F12)*3.41) -> 221.65
C13: Line Card (IP Phone) | D13: ='Tech Stack'!B53 -> C9400-LC-48P | E13: 48 | F13: =(20*30*1.3+65) -> 845 | G13: 250
C14: Line Card (AP) | D14: ='Tech Stack'!B57 -> C9400-LC-48UX | E14: 48 | F14: =(20*60*1.3+70) -> 1630 | G14: 250 | J14: Power required in chassis | K14: =SUM(F5:F14,F23) -> 4380
C15: Power Supply | D15: PWR-C4-3200WAC | F15: 3200 | G15: 950 | J15: Power provided by chassis | K15: =SUM(F15:F22) -> 9600
C16: Power Supply | D16: PWR-C4-3200WAC | F16: 3200 | G16: 950
C17: Power Supply | D17: PWR-C4-3200WAC | F17: 3200 | G17: 950
C18: Power Supply | G18: =ABS(F18)*3.41 -> 0
C19: Power Supply | G19: =ABS(F19)*3.41 -> 0
C20: Power Supply | G20: =ABS(F20)*3.41 -> 0
C21: Power Supply | G21: =ABS(F21)*3.41 -> 0
C22: Power Supply | G22: =ABS(F22)*3.41 -> 0
C23: Catalyst 9410R Fan Tray | D23: C9410-FAN | F23: 600 | G23: =ABS(F23)*3.41 -> 2046
B24: 2 | C24: UTP Patch Panel | D24: CPPKL6ATG48WBL | E24: 48
B25: 2 | C25: UTP Patch Panel | D25: CPPKL6ATG48WBL | E25: 48
B26: 2 | C26: UTP Patch Panel | D26: CPPKL6ATG48WBL | E26: 48
B27: 2 | C27: UTP Patch Panel | D27: CPPKL6ATG48WBL | E27: 48
B28: 2 | C28: UTP Patch Panel | D28: CPPKL6ATG48WBL | E28: 48
B29: 2 | C29: UTP Patch Panel | D29: CPPKL6ATG48WBL | E29: 48
B30: 2 | C30: UTP Patch Panel | D30: CPPKL6ATG48WBL | E30: 48
B31: 6 | C31: UPS | D31: SRT10KXLT | F31: 10000 | G31: 2450
B32: 6 | C32: UPS | D32: SRT10KXLT | F32: 10000 | G32: 2450
A33: Total | B33: =SUM(B4:B32) -> 39 | G33: =SUM(G4:G32) -> 14746.05
E34: Required UPS power [W] | F34: =SUM(F15:F22) -> 9600
E35: Available UPS power [W] | F35: =SUM(F31:F32) -> 20000
D37: Consum electric AC | E37: Racire AC
B38: AC 1 | C38: Daikin Sky Air Active Ducted Air Conditioner ADEAS60A | D38: 5700 | E38: 19000
B39: AC 2 | C39: Daikin Sky Air Active Ducted Air Conditioner ADEAS60A | D39: 5700 | E39: 19000
C40: Total | D40: =SUM(D38:D39) -> 11400 | E40: =SUM(E38:E39) -> 38000
B44: Nr prize simple de conectat la acest DF, valoarea se ia din etapa 2 | C44: =SUM('Tech Stack'!B41:E41) -> 266
...

Sheet IDF2
A1: Open Frame Server 44U Rack
A2: ORG Vert | B2: Spatiu ocupat in U | C2: Denumire/ tip echipament | D2: Model | E2: Scurta descriere/ nr porturi | F2: Putere electrica W | G2: Caldura disipata BTU/h | H2: ORG Vert
A3: Organizator de cabluri vertical | B3: 1 | C3: OF Patch Panel | D3: PP-72X100G-SMF | E3: 72 | H3: Organizator de cabluri vertical
B4: 13 | C4: Chassis | D4: Cisco Catalyst 9410R
C5: Supervisor | D5: ='Tech Stack'!B52 -> C9400-SUP-1XL | E5: 2 | F5: 350 | G5: =ABS(F5)*3.41 -> 1193.5
C6: Supervisor | D6: ='Tech Stack'!B52 -> C9400-SUP-1XL | E6: 2 | F6: 350 | G6: =ABS(F6)*3.41 -> 1193.5
C7: OF Line Card | D7: ='Tech Stack'!B56 -> C9400-LC-12QC (12x40GE) | E7: 12 | F7: 280 | G7: =ABS(F7)*3.41 -> 954.8
C8: Line Card (WS) | D8: ='Tech Stack'!B53 -> C9400-LC-48P | E8: 48 | F8: =(65) -> 65 | G8: =(ABS(F8)*3.41) -> 221.65
C9: Line Card (WS) | D9: ='Tech Stack'!B53 -> C9400-LC-48P | E9: 48 | F9: =(65) -> 65 | G9: =(ABS(F9)*3.41) -> 221.65
C10: Line Card (WS) | D10: ='Tech Stack'!B53 -> C9400-LC-48P | E10: 48 | F10: =(65) -> 65 | G10: =(ABS(F10)*3.41) -> 221.65
C11: Line Card (WS) | D11: ='Tech Stack'!B53 -> C9400-LC-48P | E11: 48 | F11: =(65) -> 65 | G11: =(ABS(F11)*3.41) -> 221.65
C12: Line Card (WS) | D12: ='Tech Stack'!B53 -> C9400-LC-48P | E12: 48 | F12: =(65) -> 65 | G12: =(ABS(F12)*3.41) -> 221.65
C13: Line Card (IP Phone) | D13: ='Tech Stack'!B53 -> C9400-LC-48P | E13: 48 | F13: =(20*30*1.3+65) -> 845 | G13: 250
C14: Line Card (AP) | D14: ='Tech Stack'!B57 -> C9400-LC-48UX | E14: 48 | F14: =(20*60*1.3+70) -> 1630 | G14: 250 | J14: Power required in chassis | K14: =SUM(F5:F14,F23) -> 4380
C15: Power Supply | D15: PWR-C4-3200WAC | F15: 3200 | G15: 950 | J15: Power provided by chassis | K15: =SUM(F15:F22) -> 9600
C16: Power Supply | D16: PWR-C4-3200WAC | F16: 3200 | G16: 950
C17: Power Supply | D17: PWR-C4-3200WAC | F17: 3200 | G17: 950
C18: Power Supply | G18: =ABS(F18)*3.41 -> 0
C19: Power Supply | G19: =ABS(F19)*3.41 -> 0
C20: Power Supply | G20: =ABS(F20)*3.41 -> 0
C21: Power Supply | G21: =ABS(F21)*3.41 -> 0
C22: Power Supply | G22: =ABS(F22)*3.41 -> 0
C23: Catalyst 9410R Fan Tray | D23: C9410-FAN | F23: 600 | G23: =ABS(F23)*3.41 -> 2046
B24: 2 | C24: UTP Patch Panel | D24: CPPKL6ATG48WBL | E24: 48
B25: 2 | C25: UTP Patch Panel | D25: CPPKL6ATG48WBL | E25: 48
B26: 2 | C26: UTP Patch Panel | D26: CPPKL6ATG48WBL | E26: 48
B27: 2 | C27: UTP Patch Panel | D27: CPPKL6ATG48WBL | E27: 48
B28: 2 | C28: UTP Patch Panel | D28: CPPKL6ATG48WBL | E28: 48
B29: 2 | C29: UTP Patch Panel | D29: CPPKL6ATG48WBL | E29: 48
B30: 2 | C30: UTP Patch Panel | D30: CPPKL6ATG48WBL | E30: 48
B31: 6 | C31: UPS | D31: SRT10KXLT | F31: 10000 | G31: 2450
B32: 6 | C32: UPS | D32: SRT10KXLT | F32: 10000 | G32: 2450
A33: Total | B33: =SUM(B4:B32) -> 39 | G33: =SUM(G4:G32) -> 14746.05
E34: Required UPS power [W] | F34: =SUM(F15:F22) -> 9600
E35: Available UPS power [W] | F35: =SUM(F31:F32) -> 20000
D37: Consum electric AC | E37: Racire AC
B38: AC 1 | C38: Daikin Sky Air Active Ducted Air Conditioner ADEAS60A | D38: 5700 | E38: 19000
B39: AC 2 | C39: Daikin Sky Air Active Ducted Air Conditioner ADEAS60A | D39: 5700 | E39: 19000
C40: Total | D40: =SUM(D38:D39) -> 11400 | E40: =SUM(E38:E39) -> 38000
B42: Nr prize simple de conectat la acest DF, valoarea se ia din etapa 2 | C42: =SUM('Tech Stack'!B42:E42) -> 280
...

Sheet IDF3
A1: Open Frame Server 44U Rack
A2: ORG Vert | B2: Spatiu ocupat in U | C2: Denumire/ tip echipament | D2: Model | E2: Scurta descriere/ nr porturi | F2: Putere electrica W | G2: Caldura disipata BTU/h | H2: ORG Vert
A3: Organizator de cabluri vertical | B3: 1 | C3: OF Patch Panel | D3: PP-72X100G-SMF | E3: 72 | H3: Organizator de cabluri vertical
B4: 13 | C4: Chassis | D4: Cisco Catalyst 9410R
C5: Supervisor | D5: ='Tech Stack'!B52 -> C9400-SUP-1XL | E5: 2 | F5: 350 | G5: =ABS(F5)*3.41 -> 1193.5
C6: Supervisor | D6: ='Tech Stack'!B52 -> C9400-SUP-1XL | E6: 2 | F6: 350 | G6: =ABS(F6)*3.41 -> 1193.5
C7: OF Line Card | D7: ='Tech Stack'!B56 -> C9400-LC-12QC (12x40GE) | E7: 12 | F7: 280 | G7: =ABS(F7)*3.41 -> 954.8
C8: Line Card (WS) | D8: ='Tech Stack'!B53 -> C9400-LC-48P | E8: 48 | F8: =(65) -> 65 | G8: =(ABS(F8)*3.41) -> 221.65
C9: Line Card (WS) | D9: ='Tech Stack'!B53 -> C9400-LC-48P | E9: 48 | F9: =(65) -> 65 | G9: =(ABS(F9)*3.41) -> 221.65
C10: Line Card (WS) | D10: ='Tech Stack'!B53 -> C9400-LC-48P | E10: 48 | F10: =(65) -> 65 | G10: =(ABS(F10)*3.41) -> 221.65
C11: Line Card (WS) | D11: ='Tech Stack'!B53 -> C9400-LC-48P | E11: 48 | F11: =(65) -> 65 | G11: =(ABS(F11)*3.41) -> 221.65
C12: Line Card (WS) | D12: ='Tech Stack'!B53 -> C9400-LC-48P | E12: 48 | F12: =(65) -> 65 | G12: =(ABS(F12)*3.41) -> 221.65
C13: Line Card (IP Phone) | D13: ='Tech Stack'!B53 -> C9400-LC-48P | E13: 48 | F13: =(20*30*1.3+65) -> 845 | G13: 250
C14: Line Card (AP) | D14: ='Tech Stack'!B57 -> C9400-LC-48UX | E14: 48 | F14: =(20*60*1.3+70) -> 1630 | G14: 250 | J14: Power required in chassis | K14: =SUM(F5:F14,F23) -> 4380
C15: Power Supply | D15: PWR-C4-3200WAC | F15: 3200 | G15: 950 | J15: Power provided by chassis | K15: =SUM(F15:F22) -> 9600
C16: Power Supply | D16: PWR-C4-3200WAC | F16: 3200 | G16: 950
C17: Power Supply | D17: PWR-C4-3200WAC | F17: 3200 | G17: 950
C18: Power Supply | G18: =ABS(F18)*3.41 -> 0
C19: Power Supply | G19: =ABS(F19)*3.41 -> 0
C20: Power Supply | G20: =ABS(F20)*3.41 -> 0
C21: Power Supply | G21: =ABS(F21)*3.41 -> 0
C22: Power Supply | G22: =ABS(F22)*3.41 -> 0
C23: Catalyst 9410R Fan Tray | D23: C9410-FAN | F23: 600 | G23: =ABS(F23)*3.41 -> 2046
B24: 2 | C24: UTP Patch Panel | D24: CPPKL6ATG48WBL | E24: 48
B25: 2 | C25: UTP Patch Panel | D25: CPPKL6ATG48WBL | E25: 48
B26: 2 | C26: UTP Patch Panel | D26: CPPKL6ATG48WBL | E26: 48
B27: 2 | C27: UTP Patch Panel | D27: CPPKL6ATG48WBL | E27: 48
B28: 2 | C28: UTP Patch Panel | D28: CPPKL6ATG48WBL | E28: 48
B29: 2 | C29: UTP Patch Panel | D29: CPPKL6ATG48WBL | E29: 48
B30: 2 | C30: UTP Patch Panel | D30: CPPKL6ATG48WBL | E30: 48
B31: 6 | C31: UPS | D31: SRT10KXLT | F31: 10000 | G31: 2450
B32: 6 | C32: UPS | D32: SRT10KXLT | F32: 10000 | G32: 2450
A33: Total | B33: =SUM(B4:B32) -> 39 | G33: =SUM(G4:G32) -> 14746.05
E34: Required UPS power [W] | F34: =SUM(F15:F22) -> 9600
E35: Available UPS power [W] | F35: =SUM(F31:F32) -> 20000
D37: Consum electric AC | E37: Racire AC
B38: AC 1 | C38: Daikin Sky Air Active Ducted Air Conditioner ADEAS60A | D38: 5700 | E38: 19000
B39: AC 2 | C39: Daikin Sky Air Active Ducted Air Conditioner ADEAS60A | D39: 5700 | E39: 19000
C40: Total | D40: =SUM(D38:D39) -> 11400 | E40: =SUM(E38:E39) -> 38000
B42: Nr prize simple de conectat la acest DF, valoarea se ia din etapa 2 | C42: =SUM('Tech Stack'!B43:E43) -> 244
...
